Workbook

Sheet Ponts
C2: A consolider | Y2: A consolider
C3: EVS passée | Y3: EVS passée
C4: En cas D'EVS négatif (changement pont) | Y4: En cas D'EVS négatif (changement pont)
C5: Travaux spécifiques | Y5: Travaux spécifiques
C6: RGE 25 ans | Y6: RGE 25 ans
C7: RGE 50 ans | Y7: RGE 50 ans
C8: EVS + tx suite EVS (réparation type soudures) | Y8: EVS + tx suite EVS (réparation type soudures) OU dépenses obso (ex télécommandes)
B9: En Euros | N9: NEW ! | O9: NEW ! | P9: Evaluation Speciale | S9: OPEX usine = EVS + RGM après EVS + RGE après EVS (RGE "50 ans") CAPEX = RGE 25 ans + Installation nouveaux ponts (si EVS négatif) | BJ9: =COUNTA(BJ11:BJ185) -> 147 | BK9: ROADMAP SECURISATION DES PONTS
A10: PAYS | B10: Site | C10: Pont | D10: ACCESSOIRES : Pince ou Elingue | E10: EGT | F10: EGT € | G10: COMMENTAIRES | H10: Ligne de Presse ou utilisation | I10: MES | J10: Observations | K10: Age | L10: PRIX NEUF | M10: Travaux RG ou Installation Nouveau Pont | N10: Pont à évaluer en interne par Référent Levage (MES>2008) | O10: Année Evaluation Interne | P10: Evaluation Spéciale O/N | Q10: EVS Année | R10: E/S Montant | S10: 2024 EGT | T10: 2025 OPEX DF (EVS et travaux préconisés) (EVS et travaux préconisés) | U10: 2025 RGE/RGM CAPEX IV | V10: 2025 ACHAT NEUF CAPEX IV | W10: 2026 OPEX DF (EVS et travaux préconisés) | X10: 2026 RGE/RGM CAPEX IV | Y10: 2026 ACHAT NEUF CAPEX IV | Z10: 2027 OPEX DF (EVS et travaux préconisés) | AA10: 2027 RGE/RGM CAPEX IV | AB10: 2027 ACHAT NEUF CAPEX IV | AC10: 2028 OPEX DF (EVS et travaux préconisés) | AD10: 2028 RGE/RGM CAPEX IV | AE10: 2028 ACHAT NEUF CAPEX IV | AF10: 2029 OPEX DF (EVS et travaux préconisés) | AG10: 2029 RGE/RGM CAPEX IV | AH10: 2029 ACHAT NEUF CAPEX IV | AI10: 2030 OPEX DF (EVS et travaux préconisés) | AJ10: 2030 RGE/RGM CAPEX IV | AK10: 2030 ACHAT NEUF CAPEX IV | AL10: 2031 OPEX DF (EVS et travaux préconisés) | AM10: 2031 RGE/RGM CAPEX IV | AN10: 2031 ACHAT NEUF CAPEX IV | AO10: 2032 OPEX DF (EVS et travaux préconisés) | AP10: 2032 RGE/RGM CAPEX IV | AQ10: 2032 ACHAT NEUF CAPEX IV | AR10: 2033 OPEX DF (EVS et travaux préconisés) | AS10: 2033 RGE/RGM CAPEX IV | AT10: 2033 ACHAT NEUF CAPEX IV | AU10: 2034 OPEX DF (EVS et travaux préconisés) | AV10: 2034 RGE/RGM CAPEX IV | AW10: 2034 ACHAT NEUF CAPEX IV | AX10: 2035 OPEX DF (EVS et travaux préconisés) | AY10: 2035 RGE/RGM CAPEX IV | AZ10: 2035 ACHAT NEUF CAPEX IV | BA10: 2036 OPEX DF (EVS et travaux préconisés) | BB10: 2036 RGE/RGM CAPEX IV | BC10: 2036 ACHAT NEUF CAPEX IV | BD10: 2037 OPEX DF (EVS et travaux préconisés) | BE10: 2037 RGE/RGM CAPEX IV | BF10: 2037 ACHAT NEUF CAPEX IV | BK10: USAGE : Manutention et/ou Manipulation | BL10: TYPE : Automate ou Electromécanique | BM10: ROADMAP Capex Obsolescence | BN10: ROADMAP SECURISATION
A11: 1-FRANCE | B11: Chassis | C11: Pont E4 20T 48444 SEVAL/OMIS | I11: 2012 | J11: HORS SCOPE DEPT EMB | K11: =IF(I11="","",YEAR(TODAY())-I11) -> 14 | N11: =IF(I11>2008,"Evaluation interne", " ") -> Evaluation interne | O11: =IF(I11>2008, I11+20, " ") -> 2032 | P11: N | Q11: =I11+39 -> 2051 | R11: 40000 | BJ11: Pont E4 20T 48444 SEVAL/OMIS
A12: 1-FRANCE | B12: Chassis | C12: Pont E0 46833 25 T KONECRANES | I12: 2010 | J12: HORS SCOPE DEPT EMB | K12: =IF(I12="","",YEAR(TODAY())-I12) -> 16 | M12: RGE | N12: =IF(I12>2008,"Evaluation interne", " ") -> Evaluation interne | O12: =IF(I12>2008, I12+20, " ") -> 2030 | P12: N | Q12: =I12+39 -> 2049 | R12: 40000 | AX12: 40000 | BJ12: Pont E0 46833 25 T KONECRANES | BM12: 2035
A13: 1-FRANCE | B13: Chassis | C13: SP HH3 44839 25T ADC | I13: 2008 | J13: HORS SCOPE DEPT EMB | K13: =IF(I13="","",YEAR(TODAY())-I13) -> 18 | M13: RGE | N13: =IF(I13>2008,"Evaluation interne", " ") | O13: =IF(I13>2008, I13+20, " ") | P13: N | Q13: =I13+39 -> 2047 | R13: 25000 | AR13: 50000 | BJ13: SP HH3 44839 25T ADC | BK13: Manipulation | BM13: 2033
A14: 1-FRANCE | B14: Chassis | C14: Pont E2 1470200822 4T SEVAL | I14: 2003 | J14: HORS SCOPE DEPT EMB | K14: =IF(I14="","",YEAR(TODAY())-I14) -> 23 | N14: =IF(I14>2008,"Evaluation interne", " ") | O14: =IF(I14>2008, I14+20, " ") | P14: N | Q14: =I14+39 -> 2042 | R14: 40000 | BJ14: Pont E2 1470200822 4T SEVAL
A15: 1-FRANCE | B15: Chassis | C15: Pont E2' 1470200821 8/8 T DEMAG | I15: 2003 | J15: HORS SCOPE DEPT EMB | K15: =IF(I15="","",YEAR(TODAY())-I15) -> 23 | N15: =IF(I15>2008,"Evaluation interne", " ") | O15: =IF(I15>2008, I15+20, " ") | P15: N | Q15: =I15+39 -> 2042 | R15: 40000 | BJ15: Pont E2' 1470200821 8/8 T DEMAG
A16: 1-FRANCE | B16: Chassis | C16: Pont E2 1470200820 14/14 T SEVAL | I16: 2003 | J16: HORS SCOPE DEPT EMB | K16: =IF(I16="","",YEAR(TODAY())-I16) -> 23 | M16: RGE | N16: =IF(I16>2008,"Evaluation interne", " ") | O16: =IF(I16>2008, I16+20, " ") | P16: N | Q16: =I16+39 -> 2042 | R16: 40000 | AF16: 40000 | BJ16: Pont E2 1470200820 14/14 T SEVAL | BM16: 2029
A17: 1-FRANCE | B17: Chassis | C17: Pont (SP ?) E4 1470200756 8T | I17: 2003 | J17: HORS SCOPE DEPT EMB | K17: =IF(I17="","",YEAR(TODAY())-I17) -> 23 | M17: RGE | N17: =IF(I17>2008,"Evaluation interne", " ") | O17: =IF(I17>2008, I17+20, " ") | P17: N | Q17: =I17+39 -> 2042 | R17: 40000 | AC17: 20000 | BJ17: Pont (SP ?) E4 1470200756 8T | BM17: 2028
A18: 1-FRANCE | B18: Chassis | C18: Pont E5 25 T 1470200554 SEVAL | I18: 2003 | J18: HORS SCOPE DEPT EMB | K18: =IF(I18="","",YEAR(TODAY())-I18) -> 23 | M18: RGE | N18: =IF(I18>2008,"Evaluation interne", " ") | O18: =IF(I18>2008, I18+20, " ") | P18: N | Q18: =I18+39 -> 2042 | R18: 40000 | AC18: 50000 | BJ18: Pont E5 25 T 1470200554 SEVAL | BM18: 2028
A19: 1-FRANCE | B19: Chassis | C19: Pont E6 1470000240 50T SAMETO | I19: 2001 | J19: HORS SCOPE DEPT EMB | K19: =IF(I19="","",YEAR(TODAY())-I19) -> 25 | M19: RGE 25 ans | N19: =IF(I19>2008,"Evaluation interne", " ") | O19: =IF(I19>2008, I19+20, " ") | P19: N | Q19: =I19+39 -> 2040 | R19: 40000 | AA19: 170000 | BJ19: Pont E6 1470000240 50T SAMETO | BM19: 2027 | BN19: 2025
A20: 1-FRANCE | B20: Chassis | C20: Pont E6 1470001297 50/50T SAMETO | I20: 2001 | J20: HORS SCOPE DEPT EMB | K20: =IF(I20="","",YEAR(TODAY())-I20) -> 25 | M20: RGE 25 ans | N20: =IF(I20>2008,"Evaluation interne", " ") | O20: =IF(I20>2008, I20+20, " ") | P20: N | Q20: =I20+39 -> 2040 | R20: 40000 | AA20: 170000 | BJ20: Pont E6 1470001297 50/50T SAMETO | BM20: 2027
A21: 1-FRANCE | B21: Chassis | C21: Pont E0 1470000704 25 T SEVAL | I21: 2000 | J21: HORS SCOPE DEPT EMB | K21: =IF(I21="","",YEAR(TODAY())-I21) -> 26 | M21: RGE | N21: =IF(I21>2008,"Evaluation interne", " ") | O21: =IF(I21>2008, I21+20, " ") | P21: N | Q21: =I21+39 -> 2039 | R21: 40000 | X21: 150000 | BJ21: Pont E0 1470000704 25 T SEVAL | BM21: 2026
A22: 1-FRANCE | B22: Chassis | C22: Pont E2 1479900509 16T SAMETO | I22: 1999 | J22: HORS SCOPE DEPT EMB | K22: =IF(I22="","",YEAR(TODAY())-I22) -> 27 | M22: RGE | N22: =IF(I22>2008,"Evaluation interne", " ") | O22: =IF(I22>2008, I22+20, " ") | P22: N | Q22: =I22+39 -> 2038 | R22: 40000 | X22: 120000 | BJ22: Pont E2 1479900509 16T SAMETO | BM22: 2026
A23: 1-FRANCE | B23: Chassis | C23: Pont E1 759847 20T SAMETO | I23: 1994 | J23: HORS SCOPE DEPT EMB | K23: =IF(I23="","",YEAR(TODAY())-I23) -> 32 | M23: RGE | N23: =IF(I23>2008,"Evaluation interne", " ") | O23: =IF(I23>2008, I23+20, " ") | P23: N | Q23: =I23+39 -> 2033 | R23: 40000 | X23: 150000 | BJ23: Pont E1 759847 20T SAMETO | BM23: 2026
A24: 1-FRANCE | B24: Chassis | C24: Pont E1 759848 20/20 T SAMETO (RGE 2019) | I24: 1994 | J24: HORS SCOPE DEPT EMB | K24: =IF(I24="","",YEAR(TODAY())-I24) -> 32 | N24: =IF(I24>2008,"Evaluation interne", " ") | O24: =IF(I24>2008, I24+20, " ") | P24: N | Q24: =I24+39 -> 2033 | R24: 40000 | BJ24: Pont E1 759848 20/20 T SAMETO (RGE 2019)
A25: 1-FRANCE | B25: LHA | C25: Pont J12 63T | D25: Pince | H25: L08 | I25: 2006 | K25: =IF(I25="","",YEAR(TODAY())-I25) -> 20 | L25: ='DEMARCHE EVS'!B9 -> 950000 | M25: RGE | N25: =IF(I25>2008,"Evaluation interne", " ") | O25: =IF(I25>2008, I25+20, " ") | P25: NC | Q25: =I25+39 -> 2045 | R25: 40000 | AC25: 60000 | BJ25: Pont J12 | BM25: 2028
A26: 1-FRANCE | B26: LHA | C26: Pont J11 63T | D26: Pince | H26: L11 | I26: 2006 | K26: =IF(I26="","",YEAR(TODAY())-I26) -> 20 | M26: RGE | N26: =IF(I26>2008,"Evaluation interne", " ") | O26: =IF(I26>2008, I26+20, " ") | Q26: =I26+39 -> 2045 | R26: 40000 | AM26: 170000 | BJ26: Pont J11 | BM26: 2029
A27: 1-FRANCE | B27: LHA | C27: Pince outils J11 | D27: PINCE | H27: L11 | I27: 1999 | K27: =IF(I27="","",YEAR(TODAY())-I27) -> 27 | M27: RG | N27: =IF(I27>2008,"Evaluation interne", " ") | O27: =IF(I27>2008, I27+20, " ") | P27: NC | U27: 100000
A28: 1-FRANCE | B28: LHA | C28: Pince à outil J12 | D28: PINCE | H28: STOCKAGE | I28: 1999 | K28: =IF(I28="","",YEAR(TODAY())-I28) -> 27 | L28: 220000 | M28: RGM | N28: =IF(I28>2008,"Evaluation interne", " ") | O28: =IF(I28>2008, I28+20, " ") | P28: NC | X28: 85000
A29: 1-FRANCE | B29: LHA | C29: Pont J3 63/63T CAILLARD | D29: Elingue | H29: MAP/MAINTENANCE | I29: 1970 | J29: RGE 1998 | K29: =IF(I29="","",YEAR(TODAY())-I29) -> 56 | L29: 1170000 | M29: 2026 prov pour travaux / Installation nouveaux ponts 2027 | N29: =IF(I29>2008,"Evaluation interne", " ") | O29: =IF(I29>2008, I29+20, " ") | P29: N | Q29: 2026 | R29: 40000 | W29: 69000 | AA29: 170000 | AE29: 1170000 | BJ29: Pont J3 63/63T CAILLARD | BM29: 2026
A30: 1-FRANCE | B30: LHA | C30: Semi-portique N°1 J3 CHSL HUGO 10T | D30: Elingue | H30: MAP/MAINTENANCE | I30: 1979 | K30: =IF(I30="","",YEAR(TODAY())-I30) -> 47 | L30: 120000 | M30: RG | N30: =IF(I30>2008,"Evaluation interne", " ") | O30: =IF(I30>2008, I30+20, " ") | P30: N | Q30: 2026 | R30: 20000 | W30: 20000 | BJ30: Semi-portique N°1 J3 CHSL | BK30: Manipulation
A31: 1-FRANCE | B31: LHA | C31: Semi-portique N°2 J3 CHSL (10T SAMETO?)-STOP 06/02 | D31: Elingue | H31: MAP/MAINTENANCE | I31: 1979 | J31: RGE 2003 | K31: =IF(I31="","",YEAR(TODAY())-I31) -> 47 | L31: 120000 | M31: RG | N31: =IF(I31>2008,"Evaluation interne", " ") | O31: =IF(I31>2008, I31+20, " ") | P31: N | Q31: 2026 | R31: 20000 | W31: =20000 -> 20000 | BJ31: Semi-portqiue N°2 J3 CHSL | BK31: Manipulation
A32: 1-FRANCE | B32: LHA | C32: Pont J1sud 63T CAILLARD | H32: 80%OUTILS / 20%BOBINES | I32: 1970 | K32: =IF(I32="","",YEAR(TODAY())-I32) -> 56 | M32: RGE 50 ans | N32: =IF(I32>2008,"Evaluation interne", " ") | O32: =IF(I32>2008, I32+20, " ") | P32: O | Q32: 2035 | R32: 40000 | T32: =40000 + 25000 -> 65000 | AA32: 170000 | AX32: 40000 | BC32: 1120000 | BJ32: Pont J1sud 63T | BM32: 2026
A33: 1-FRANCE | B33: LHA | C33: J1 Nord | D33: Pince | H33: STOCKAGE | K33: =IF(I33="","",YEAR(TODAY())-I33) | N33: =IF(I33>2008,"Evaluation interne", " ") | O33: =IF(I33>2008, I33+20, " ") | BJ33: J1 Nord
A34: 1-FRANCE | B34: LHA | C34: J2 Nord | D34: Elingue | E34: 2027 | F34: 80000 | H34: STOCKAGE | K34: =IF(I34="","",YEAR(TODAY())-I34) | N34: =IF(I34>2008,"Evaluation interne", " ") | O34: =IF(I34>2008, I34+20, " ") | BJ34: J2 Nord | BN34: 2025
A35: 1-FRANCE | B35: LHA | C35: J2 Sud | D35: Elingue | E35: 2026 | F35: 80000 | H35: PAL/PAVAR | K35: =IF(I35="","",YEAR(TODAY())-I35) | N35: =IF(I35>2008,"Evaluation interne", " ") | O35: =IF(I35>2008, I35+20, " ") | BJ35: J2 Sud
A36: 1-FRANCE | B36: MCA | C36: Pont 63T XLHS SECAL | D36: Pince | H36: XL HS | I36: 2019 | K36: =IF(I36="","",YEAR(TODAY())-I36) -> 7 | N36: =IF(I36>2008,"Evaluation interne", " ") -> Evaluation interne | O36: =IF(I36>2008, I36+20, " ") -> 2039 | P36: N | Q36: =I36+20 -> 2039 | R36: 40000 | AD36: 140000 | BJ36: Pont 63T XLHS SECAL | BM36: 2028
A37: 1-FRANCE | B37: MCA | C37: PINCE 50T XXL HS | H37: XXL HS | I37: 2019 | K37: =IF(I37="","",YEAR(TODAY())-I37) -> 7 | N37: =IF(I37>2008,"Evaluation interne", " ") -> Evaluation interne | O37: =IF(I37>2008, I37+20, " ") -> 2039 | Q37: 2039
A38: 1-FRANCE | B38: MCA | C38: Pont 50/50 T XLHS SECAL | D38: Pince | H38: MAP XL | I38: 2019 | K38: =IF(I38="","",YEAR(TODAY())-I38) -> 7 | N38: =IF(I38>2008,"Evaluation interne", " ") -> Evaluation interne | O38: =IF(I38>2008, I38+20, " ") -> 2039 | P38: N | Q38: =I38+39 -> 2058 | R38: 40000 | AG38: 170000 | BJ38: Pont 50/50 T XLHS SECAL | BM38: 2029
A39: 1-FRANCE | B39: MCA | C39: Pont 25 T PAL SEVAL | D39: Elingue | E39: EGT | H39: PAL | I39: 2001 | K39: =IF(I39="","",YEAR(TODAY())-I39) -> 25 | M39: RGE 25 ans | N39: =IF(I39>2008,"Evaluation interne", " ") | O39: =IF(I39>2008, I39+20, " ") | P39: N | Q39: =I39+39 -> 2040 | R39: 40000 | U39: 135000 | Y39: 290000 | BJ39: Pont 25 T PAL SEVAL | BM39: 2025
A40: 1-FRANCE | B40: MCA | C40: Pont 32 T Appro bobines SAMETO | D40: Pince | H40: BOBINES | I40: 2000 | K40: =IF(I40="","",YEAR(TODAY())-I40) -> 26 | M40: RGE 25 ans | N40: =IF(I40>2008,"Evaluation interne", " ") | O40: =IF(I40>2008, I40+20, " ") | P40: N | Q40: =I40+39 -> 2039 | R40: 40000 | AD40: 170000 | BJ40: Pont 32 T Appro bobines SAMETO | BM40: 2027
A41: 1-FRANCE | B41: MCA | C41: Pont 25/25T Nord SAMETO | D41: Elingue | H41: MAP (et ex L3) | I41: 1998 | K41: =IF(I41="","",YEAR(TODAY())-I41) -> 28 | M41: RGE 25 ans | N41: =IF(I41>2008,"Evaluation interne", " ") | O41: =IF(I41>2008, I41+20, " ") | P41: N | Q41: =I41+39 -> 2037 | R41: 40000 | AA41: 0 | BJ41: Pont 25/25T Nord SAMETO | BM41: 2025 | BN41: 2025
...

Sheet TCD12022026
A3: Site | B3: Somme de 2026 OPEX DF (EVS et travaux préconisés) | C3: Somme de 2026 RGE/RGM CAPEX IV | D3: Somme de 2026 ACHAT NEUF CAPEX IV | E3: Somme de 2027 OPEX DF (EVS et travaux préconisés) | F3: Somme de 2027 RGE/RGM CAPEX IV | G3: Somme de 2027 ACHAT NEUF CAPEX IV | H3: Somme de 2028 OPEX DF (EVS et travaux préconisés) | I3: Somme de 2028 ACHAT NEUF CAPEX IV | J3: Somme de 2028 RGE/RGM CAPEX IV | K3: Somme de 2029 OPEX DF (EVS et travaux préconisés) | L3: Somme de 2029 RGE/RGM CAPEX IV | M3: Somme de 2029 ACHAT NEUF CAPEX IV | N3: Somme de 2030 OPEX DF (EVS et travaux préconisés) | O3: Somme de 2030 RGE/RGM CAPEX IV | P3: Somme de 2030 ACHAT NEUF CAPEX IV | Q3: Somme de 2031 OPEX DF (EVS et travaux préconisés) | R3: Somme de 2031 RGE/RGM CAPEX IV | S3: Somme de 2031 ACHAT NEUF CAPEX IV
A4: Bursa | F4: 160000 | O4: 510000 | R4: 170000
A5: Busan
A6: Chassis | C6: 420000 | F6: 340000 | H6: 70000 | K6: 40000
A7: CHENNAI
A8: Cordoba | B8: 39000
A9: Curitiba | F9: 600000 | R9: 300000
A10: LHA | B10: 109000 | C10: 85000 | F10: 340000 | H10: 60000 | I10: 1170000 | R10: 170000
A11: Matrite | H11: 40000
A12: MCA | D12: 290000 | F12: 340000 | J12: 310000 | L12: 170000
A13: PAL | C13: 329000 | E13: 120000 | L13: 170000 | O13: 340000
A14: PITESTI | E14: 15000 | F14: 90000 | H14: 15000 | Q14: 5000
A15: REVOZ | B15: 50000 | D15: 450000 | F15: 50000 | L15: 170000 | O15: 170000 | R15: 170000
A16: Tanger | B16: 65000 | E16: 65000 | G16: 1375000 | H16: 65000 | K16: 65000 | N16: 65000
A17: UGB | B17: 280000 | E17: 40000 | F17: 680000 | I17: 1700000 | J17: 340000 | L17: 340000 | N17: 40000 | O17: 170000 | R17: 170000
A18: UPL | B18: 113600 | E18: 117000 | F18: 230000 | G18: 860000 | H18: 8600 | I18: 860000 | J18: 170000 | N18: 48000 | O18: 340000 | S18: 850000
A19: VLL | F19: 490000 | J19: 340000 | L19: 340000 | O19: 340000 | R19: 340000
A20: Total général | B20: 656600 | C20: 834000 | D20: 740000 | E20: 357000 | F20: 3320000 | G20: 2235000 | H20: 258600 | I20: 3730000 | J20: 1160000 | K20: 105000 | L20: 1190000 | N20: 153000 | O20: 1870000 | Q20: 5000 | R20: 1320000 | S20: 850000

Sheet EVENT GATES
A2: Somme de EGT € | D2: EGT
A3: PAYS | B3: Site | C3: Pont | D3: 2025 | E3: 2026 | F3: 2027 | G3: 2028
A4: 1-FRANCE | B4: LHA | C4: J2 Nord | F4: 80000
C5: J2 Sud | E5: 80000
B6: MCA | C6: Pont 25/25 T Sud SEVAL L01 | F6: 80000
B7: UGB | C7: Pont A12 Caillard/SAMETO 63 T | E7: 80000
B8: UPL | C8: Pont AA5 28 T SEVAL | F8: 80000
A9: 2-ESPAGNE | B9: PAL | C9: Pont 45/45T PG7 GH | F9: 83000
B10: VLL | C10: Pont 32/32 T SEVAL L5 | E10: 88000
A11: COREE | B11: Busan | C11: Pont 3-2 40 T pour presse 5100 T
A12: INDE | B12: CHENNAI | C12: Pont N°6 40T DEMAG | F12: 55000
C13: Pont N°8 40 T DEMAG | F13: 55000
A14: MAROC | B14: Tanger | C14: Pont 52 32 T ADC | F14: 66000
C15: Pont 607 32 T KONECRANES | E15: 66000
A16: ROUMANIE | B16: PITESTI | C16: Pont 14 TGSE 50 T PROMPT | E16: 65000
C17: Pont 16 HS 50/25 T ADC | F17: 65000
C18: Pont 5 32/8T PROMPT | E18: 65000
A19: TURQUIE | B19: Bursa | C19: Pont 45/45 T XLHS GMT | D19: 55000
C20: Pont 50/20 T TGP 100 GMT | F20: 55000
C21: Pont XL HS GMT | E21: 55000
A22: Total général | D22: 55000 | E22: 499000 | F22: 619000
D29: =COUNTA(D4:D22) -> 2 | E29: =COUNTA(E4:E22) -> 8 | F29: =COUNTA(F4:F21) -> 9

Sheet Règles
A1: Règles | B1: Date | C1: commentaires
A2: Règle | B2: 45471 | C2: J’ai mis 39 ans pour l’EVS après la date du PONT. 40k€ pour PONT et 25k€ pour SP.
B3: 45471 | C3: 1. Il manque le PONT BURSA XL de 2025 ? Pont 45/45 T XLHS GMT ?
B4: 45471 | C4: 2. Les petites RGE sont changement de variateurs et chemin de roulement.
B5: 45471 | C5: 3. J’ai mis en rouge les gros montants qu’on avait déjà identifié dans la base. Les gros montants c’est au cas où l’EVS est négatif.
B6: 45477 | C6: 4. A compléter les montants de RGE ? Fait en jaune pour approx
A7: Règle | B7: 45471 | C7: Prolongation possible après EVS positif => 3 ans en général au mieux 5/10 ans et au pire 12 mois
A8: Règle | B8: 45471 | C8: 40 ans théorique - Au bout de 39 ans , vérifier l'EVS. Pont ADC +19 ans et PONT KONECRANE +39 ans
A9: Règle | B9: 45471 | C9: RG ISCIR - Règlement spéciale Roumanie tous les 15 ans

Sheet CPI SAP
A1: Site | B1: Project | C1: Project name | D1: CATEGORIE | E1: 2025 | F1: Budget 25 | G1: 2024 | H1: 2026 | I1: 2027 | J1: 2028
A2: CURITIBA USINE A.SENNA | B2: EHI287600 | C2: Pont Roulant 1 TGSE 1 | D2: PONT | E2: 0,00 | F2: 0,00 | G2: 0 | H2: 400 000 € | I2: 0 | J2: 0
A3: CURITIBA USINE A.SENNA | B3: EHI287700 | C3: Pont Roulant 1 TGSE 2 | D3: PONT | E3: 0,00 | F3: 0,00 | G3: 0 | H3: 400 000 € | I3: 0 | J3: 0
A4: TANGER | B4: EII072000 | C4: PONT EMBOUTISSAGE | D4: PONT | E4: 0,00 | F4: 0,00 | G4: 0 | H4: 400 000 € | I4: 0 | J4: 0
A5: BURSA | B5: EGI075700 | C5: PONT XL + TRANSBORDEUR BURSA | D5: CAPACITAIRE | E5: 1 574 000,00 | F5: 1 440 000,00 | G5: 60 000 € | H5: 0 | I5: 0 | J5: 0
A6: MIOVENI (DACIA) | B6: EII063800 | C6: Pont roulant 15 HS PITESTI | D6: PONT | E6: 0,00 | F6: 0,00 | G6: 75 000 € | H6: 0 | I6: 0 | J6: 0
A7: DOUAI | B7: EHI153200 | C7: L21 UGB remplacement pont A12 | D7: PONT | E7: 0,00 | F7: 0,00 | G7: 0 | H7: 0 | I7: 0 | J7: 900 000 €
A8: DOUAI | B8: EHI153500 | C8: UGB remplacement pont A18 | D8: PONT | E8: 0,00 | F8: 0,00 | G8: 0 | H8: 800 000 € | I8: 0 | J8: 0
A9: FLINS | B9: EHI154900 | C9: UPL Pont L62 Poutres AB6+ RG Pinces | D9: PONT | E9: 0,00 | F9: 0,00 | G9: 0 | H9: 1 | I9: 0 | J9: 0
A10: FLINS | B10: EHI155000 | C10: UPL remplacement Ponts RA Sud + RGE AB5 | D10: PONT | E10: 0,00 | F10: 0,00 | G10: 0 | H10: 850 000 € | I10: 0 | J10: 0
A11: FLINS | B11: EHI155100 | C11: UPL rplct Pont RA Centre RGE Ponts AB1 2 | D11: PONT | E11: 0,00 | F11: 0,00 | G11: 0 | H11: 860 000 € | I11: 0 | J11: 0
A12: MAUBEUGE | B12: EHI153600 | C12: MCA RGE PONT 25T PAL (zone PAL )​ | D12: PONT | E12: 135 000,00 | F12: 0,00 | G12: 0 | H12: 0 | I12: 0 | J12: 0
A13: MAUBEUGE | B13: EHI153700 | C13: MCA RGE SP25T + Pont 80 T | D13: PONT | E13: 0,00 | F13: 0,00 | G13: 0 | H13: 300 000 € | I13: 0 | J13: 0
A14: MAUBEUGE | B14: EII143100 | C14: MCA RGE PONT 25T Nord | D14: PONT | E14: 0,00 | F14: 0,00 | G14: 0 | H14: 155 000 € | I14: 0 | J14: 0
A15: NOVO MESTO | B15: EEI223300 | C15: REV RG PONT N°4 Travée MAP | D15: PONT | E15: 400 000,00 | F15: 0,00 | G15: 0 | H15: 0 | I15: 0 | J15: 0
A16: PALENCIA | B16: EDI286300 | C16: L5 PAL AUGMENTATION CAPA ALU - 2ème PONT | D16: CAPACITAIRE LIE | E16: 0,00 | F16: 0,00 | G16: 0 | H16: 0 | I16: 0 | J16: 0
A17: DOUAI | B17: EHI153400 | C17: UGB Remplacement PONT SP A16 | D17: PONT | H17: 250 000 €
A18: MAUBEUGE | B18: EHI153800 | C18: MCA RGE 25T sud + 32T bobines | D18: PONT | H18: 290 000€
A19: SANDOUVILLE | B19: EHI154500 | C19: LHA anti crabe J11 + RG Pince J11 | D19: PONT | E19: 200 000€
A20: SANDOUVILLE | B20: EHI154600 | C20: LHA Remplacement J1 Sud + RG voie de rlt | D20: PONT | H20: 1 120 000€
A21: SANDOUVILLE | B21: EHI154700 | C21: LHA Remplacement J3 + remplacement rails | D21: PONT | H21: 1 170 000€
A22: PROVISIONS
A23: RSAS | B23: AAI823300 | C23: PROVISION SECURISATION MOYENS LEVAGE | D23: PONT | H23: 1000000
A24: TANGER | B24: EII072000 | C24: PONT | D24: PONT | H24: 400000
A25: NOVO MESTO | B25: EHI251500 | C25: REV RGM Moyens de Levage | D25: PONT | H25: 300000

Sheet SAUVPonts FEV26
C2: A consolider | V2: A consolider
C3: EVS passée | V3: EVS passée
C4: En cas D'EVS négatif (changement pont) | V4: En cas D'EVS négatif (changement pont)
C5: Travaux spécifiques | V5: Travaux spécifiques
C6: RGE 25 ans | V6: RGE 25 ans
C7: RGE 50 ans | V7: RGE 50 ans
C8: EVS + tx suite EVS (réparation type soudures) | V8: EVS + tx suite EVS (réparation type soudures)
B9: En Euros | K9: NEW ! | L9: NEW ! | M9: Evaluation Speciale | P9: OPEX usine = EVS + RGM après EVS + RGE après EVS (RGE "50 ans") CAPEX = RGE 25 ans + Installation nouveaux ponts (si EVS négatif) | BJ9: =COUNTA(BJ11:BJ181) -> 151 | BK9: ROADMAP SECURISATION DES PONTS
A10: PAYS | B10: Site | C10: Pont | D10: ACCESSOIRES : Pince ou Elingue | E10: Ligne de Presse ou utilisation | F10: MES | G10: Observations | H10: Age | I10: PRIX NEUF | J10: Travaux RG ou Installation Nouveau Pont | K10: Pont à évaluer en interne par Référent Levage (MES>2008) | L10: Année Evaluation Interne | M10: Evaluation Spéciale O/N | N10: EVS Année | O10: E/S Montant | P10: 2024 | Q10: 2025 OPEX DF (EVS et travaux préconisés) (EVS et travaux préconisés) | R10: 2025 RGE/RGM CAPEX IV | S10: 2025 ACHAT NEUF CAPEX IV | T10: 2026 OPEX DF (EVS et travaux préconisés) | U10: 2026 RGE/RGM CAPEX IV | V10: 2026 ACHAT NEUF CAPEX IV | W10: 2027 OPEX DF (EVS et travaux préconisés) | X10: 2027 RGE/RGM CAPEX IV | Y10: 2027 ACHAT NEUF CAPEX IV | Z10: 2028 OPEX DF (EVS et travaux préconisés) | AA10: 2028 RGE/RGM CAPEX IV | AB10: 2028 ACHAT NEUF CAPEX IV | AC10: 2029 OPEX DF (EVS et travaux préconisés) | AD10: 2029 RGE/RGM CAPEX IV | AE10: 2029 ACHAT NEUF CAPEX IV | AF10: 2030 OPEX DF (EVS et travaux préconisés) | AG10: 2030 RGE/RGM CAPEX IV | AH10: 2030 ACHAT NEUF CAPEX IV | AI10: 2031 OPEX DF (EVS et travaux préconisés) | AJ10: 2031 RGE/RGM CAPEX IV | AK10: 2031 ACHAT NEUF CAPEX IV | AL10: 2032 OPEX DF (EVS et travaux préconisés) | AM10: 2032 RGE/RGM CAPEX IV | AN10: 2032 ACHAT NEUF CAPEX IV | AO10: 2033 OPEX DF (EVS et travaux préconisés) | AP10: 2033 RGE/RGM CAPEX IV | AQ10: 2033 ACHAT NEUF CAPEX IV | AR10: 2034 OPEX DF (EVS et travaux préconisés) | AS10: 2034 RGE/RGM CAPEX IV | AT10: 2034 ACHAT NEUF CAPEX IV | AU10: 2035 OPEX DF (EVS et travaux préconisés) | AV10: 2035 RGE/RGM CAPEX IV | AW10: 2035 ACHAT NEUF CAPEX IV | AX10: 2036 OPEX DF (EVS et travaux préconisés) | AY10: 2036 RGE/RGM CAPEX IV | AZ10: 2036 ACHAT NEUF CAPEX IV | BA10: 2037 OPEX DF (EVS et travaux préconisés) | BB10: 2037 RGE/RGM CAPEX IV | BC10: 2037 ACHAT NEUF CAPEX IV | BD10: EGT | BE10: COMMENTAIRES ER SUIVI BAI | BK10: USAGE : Manutention et/ou Manipulation | BL10: TYPE : Automate ou Electromécanique | BM10: ROADMAP Capex Obsolescence | BN10: ROADMAP SECURISATION
A11: 1-FRANCE | B11: Chassis | C11: Pont E4 20T 48444 SEVAL/OMIS | F11: 2012 | G11: HORS SCOPE DEPT EMB | H11: =IF(F11="","",YEAR(TODAY())-F11) -> 14 | K11: =IF(F11>2008,"Evaluation interne", " ") -> Evaluation interne | L11: =IF(F11>2008, F11+20, " ") -> 2032 | M11: N | N11: =F11+39 -> 2051 | O11: 40000 | BJ11: Pont E4 20T 48444 SEVAL/OMIS
A12: 1-FRANCE | B12: Chassis | C12: Pont E0 46833 25 T KONECRANES | F12: 2010 | G12: HORS SCOPE DEPT EMB | H12: =IF(F12="","",YEAR(TODAY())-F12) -> 16 | J12: RGE | K12: =IF(F12>2008,"Evaluation interne", " ") -> Evaluation interne | L12: =IF(F12>2008, F12+20, " ") -> 2030 | M12: N | N12: =F12+39 -> 2049 | O12: 40000 | AU12: 40000 | BJ12: Pont E0 46833 25 T KONECRANES | BM12: 2035
A13: 1-FRANCE | B13: Chassis | C13: SP HH3 44839 25T ADC | F13: 2008 | G13: HORS SCOPE DEPT EMB | H13: =IF(F13="","",YEAR(TODAY())-F13) -> 18 | J13: RGE | K13: =IF(F13>2008,"Evaluation interne", " ") | L13: =IF(F13>2008, F13+20, " ") | M13: N | N13: =F13+39 -> 2047 | O13: 25000 | AO13: 50000 | BJ13: SP HH3 44839 25T ADC | BK13: Manipulation | BM13: 2033
A14: 1-FRANCE | B14: Chassis | C14: Pont E2 1470200822 4T SEVAL | F14: 2003 | G14: HORS SCOPE DEPT EMB | H14: =IF(F14="","",YEAR(TODAY())-F14) -> 23 | K14: =IF(F14>2008,"Evaluation interne", " ") | L14: =IF(F14>2008, F14+20, " ") | M14: N | N14: =F14+39 -> 2042 | O14: 40000 | BJ14: Pont E2 1470200822 4T SEVAL
A15: 1-FRANCE | B15: Chassis | C15: Pont E2' 1470200821 8/8 T DEMAG | F15: 2003 | G15: HORS SCOPE DEPT EMB | H15: =IF(F15="","",YEAR(TODAY())-F15) -> 23 | K15: =IF(F15>2008,"Evaluation interne", " ") | L15: =IF(F15>2008, F15+20, " ") | M15: N | N15: =F15+39 -> 2042 | O15: 40000 | BJ15: Pont E2' 1470200821 8/8 T DEMAG
A16: 1-FRANCE | B16: Chassis | C16: Pont E2 1470200820 14/14 T SEVAL | F16: 2003 | G16: HORS SCOPE DEPT EMB | H16: =IF(F16="","",YEAR(TODAY())-F16) -> 23 | J16: RGE | K16: =IF(F16>2008,"Evaluation interne", " ") | L16: =IF(F16>2008, F16+20, " ") | M16: N | N16: =F16+39 -> 2042 | O16: 40000 | AC16: 40000 | BJ16: Pont E2 1470200820 14/14 T SEVAL | BM16: 2029
A17: 1-FRANCE | B17: Chassis | C17: Pont (SP ?) E4 1470200756 8T | F17: 2003 | G17: HORS SCOPE DEPT EMB | H17: =IF(F17="","",YEAR(TODAY())-F17) -> 23 | J17: RGE | K17: =IF(F17>2008,"Evaluation interne", " ") | L17: =IF(F17>2008, F17+20, " ") | M17: N | N17: =F17+39 -> 2042 | O17: 40000 | Z17: 20000 | BJ17: Pont (SP ?) E4 1470200756 8T | BM17: 2028
A18: 1-FRANCE | B18: Chassis | C18: Pont E5 25 T 1470200554 SEVAL | F18: 2003 | G18: HORS SCOPE DEPT EMB | H18: =IF(F18="","",YEAR(TODAY())-F18) -> 23 | J18: RGE | K18: =IF(F18>2008,"Evaluation interne", " ") | L18: =IF(F18>2008, F18+20, " ") | M18: N | N18: =F18+39 -> 2042 | O18: 40000 | Z18: 50000 | BJ18: Pont E5 25 T 1470200554 SEVAL | BM18: 2028
A19: 1-FRANCE | B19: Chassis | C19: Pont E6 1470000240 50T SAMETO | F19: 2001 | G19: HORS SCOPE DEPT EMB | H19: =IF(F19="","",YEAR(TODAY())-F19) -> 25 | J19: RGE 25 ans | K19: =IF(F19>2008,"Evaluation interne", " ") | L19: =IF(F19>2008, F19+20, " ") | M19: N | N19: =F19+39 -> 2040 | O19: 40000 | X19: 170000 | BJ19: Pont E6 1470000240 50T SAMETO | BM19: 2027 | BN19: 2025
A20: 1-FRANCE | B20: Chassis | C20: Pont E6 1470001297 50/50T SAMETO | F20: 2001 | G20: HORS SCOPE DEPT EMB | H20: =IF(F20="","",YEAR(TODAY())-F20) -> 25 | J20: RGE 25 ans | K20: =IF(F20>2008,"Evaluation interne", " ") | L20: =IF(F20>2008, F20+20, " ") | M20: N | N20: =F20+39 -> 2040 | O20: 40000 | X20: 170000 | BJ20: Pont E6 1470001297 50/50T SAMETO | BM20: 2027
A21: 1-FRANCE | B21: Chassis | C21: Pont E0 1470000704 25 T SEVAL | F21: 2000 | G21: HORS SCOPE DEPT EMB | H21: =IF(F21="","",YEAR(TODAY())-F21) -> 26 | J21: RGE | K21: =IF(F21>2008,"Evaluation interne", " ") | L21: =IF(F21>2008, F21+20, " ") | M21: N | N21: =F21+39 -> 2039 | O21: 40000 | U21: 150000 | BJ21: Pont E0 1470000704 25 T SEVAL | BM21: 2026
A22: 1-FRANCE | B22: Chassis | C22: Pont E2 1479900509 16T SAMETO | F22: 1999 | G22: HORS SCOPE DEPT EMB | H22: =IF(F22="","",YEAR(TODAY())-F22) -> 27 | J22: RGE | K22: =IF(F22>2008,"Evaluation interne", " ") | L22: =IF(F22>2008, F22+20, " ") | M22: N | N22: =F22+39 -> 2038 | O22: 40000 | U22: 120000 | BJ22: Pont E2 1479900509 16T SAMETO | BM22: 2026
A23: 1-FRANCE | B23: Chassis | C23: Pont E1 759847 20T SAMETO | F23: 1994 | G23: HORS SCOPE DEPT EMB | H23: =IF(F23="","",YEAR(TODAY())-F23) -> 32 | J23: RGE | K23: =IF(F23>2008,"Evaluation interne", " ") | L23: =IF(F23>2008, F23+20, " ") | M23: N | N23: =F23+39 -> 2033 | O23: 40000 | U23: 150000 | BJ23: Pont E1 759847 20T SAMETO | BM23: 2026
A24: 1-FRANCE | B24: Chassis | C24: Pont E1 759848 20/20 T SAMETO (RGE 2019) | F24: 1994 | G24: HORS SCOPE DEPT EMB | H24: =IF(F24="","",YEAR(TODAY())-F24) -> 32 | K24: =IF(F24>2008,"Evaluation interne", " ") | L24: =IF(F24>2008, F24+20, " ") | M24: N | N24: =F24+39 -> 2033 | O24: 40000 | BJ24: Pont E1 759848 20/20 T SAMETO (RGE 2019)
A25: 1-FRANCE | B25: LHA | C25: Pont J12 63T | D25: Pince | E25: L08 | F25: 2006 | H25: =IF(F25="","",YEAR(TODAY())-F25) -> 20 | I25: ='DEMARCHE EVS'!B9 -> 950000 | J25: RGE | K25: =IF(F25>2008,"Evaluation interne", " ") | L25: =IF(F25>2008, F25+20, " ") | M25: NC | N25: =F25+39 -> 2045 | O25: 40000 | Z25: 60000 | BJ25: Pont J12 | BM25: 2028
A26: 1-FRANCE | B26: LHA | C26: Pont J11 63T | D26: Pince | E26: L11 | F26: 2006 | H26: =IF(F26="","",YEAR(TODAY())-F26) -> 20 | J26: RGE | K26: =IF(F26>2008,"Evaluation interne", " ") | L26: =IF(F26>2008, F26+20, " ") | N26: =F26+39 -> 2045 | O26: 40000 | AJ26: 170000 | BJ26: Pont J11 | BM26: 2029
A27: 1-FRANCE | B27: LHA | C27: Pince outils J11 | D27: PINCE | E27: L11 | F27: 1999 | H27: =IF(F27="","",YEAR(TODAY())-F27) -> 27 | J27: RG | K27: =IF(F27>2008,"Evaluation interne", " ") | L27: =IF(F27>2008, F27+20, " ") | M27: NC | R27: 100000
A28: 1-FRANCE | B28: LHA | C28: Pince à outil J12 | D28: PINCE | E28: STOCKAGE | F28: 1999 | H28: =IF(F28="","",YEAR(TODAY())-F28) -> 27 | I28: 220000 | J28: RGM | K28: =IF(F28>2008,"Evaluation interne", " ") | L28: =IF(F28>2008, F28+20, " ") | M28: NC | U28: 85000
A29: 1-FRANCE | B29: LHA | C29: Semi-portique N°1 J3 CHSL | E29: n fc | F29: 1979 | H29: =IF(F29="","",YEAR(TODAY())-F29) -> 47 | I29: 120000 | J29: RG | K29: =IF(F29>2008,"Evaluation interne", " ") | L29: =IF(F29>2008, F29+20, " ") | M29: N | N29: 2026 | O29: 20000 | T29: 20000 | BJ29: Semi-portique N°1 J3 CHSL | BK29: Manipulation
A30: 1-FRANCE | B30: LHA | C30: Semi-portique N°2 J3 CHSL (10T SAMETO?)-STOP 06/02 | E30: MAP/MAINTENANCE | F30: 1979 | H30: =IF(F30="","",YEAR(TODAY())-F30) -> 47 | I30: 120000 | J30: RG | K30: =IF(F30>2008,"Evaluation interne", " ") | L30: =IF(F30>2008, F30+20, " ") | M30: N | N30: 2026 | O30: 20000 | T30: =20000 -> 20000 | BJ30: Semi-portqiue N°2 J3 CHSL | BK30: Manipulation
A31: 1-FRANCE | B31: LHA | C31: Pont J1sud 63T | E31: 80%OUTILS / 20%BOBINES | F31: 1970 | H31: =IF(F31="","",YEAR(TODAY())-F31) -> 56 | J31: RGE 50 ans | K31: =IF(F31>2008,"Evaluation interne", " ") | L31: =IF(F31>2008, F31+20, " ") | M31: O | N31: 2035 | O31: 40000 | Q31: =40000 + 25000 -> 65000 | X31: 170000 | AU31: 40000 | AW31: 1120000 | BJ31: Pont J1sud 63T | BM31: 2026
A32: 1-FRANCE | B32: LHA | C32: Pont J3 63/63T CAILLARD | E32: MAP/MAINTENANCE | F32: 1970 | H32: =IF(F32="","",YEAR(TODAY())-F32) -> 56 | I32: 1170000 | J32: 2026 prov pour travaux / Installation nouveaux ponts 2027 | K32: =IF(F32>2008,"Evaluation interne", " ") | L32: =IF(F32>2008, F32+20, " ") | M32: N | N32: 2026 | O32: 40000 | T32: 69000 | X32: 170000 | AB32: 1170000 | BJ32: Pont J3 63/63T CAILLARD | BM32: 2026
A33: 1-FRANCE | B33: LHA | C33: Chemins de roulement J3 | E33: MAP/MAINTENANCE | F33: 1970 | H33: =IF(F33="","",YEAR(TODAY())-F33) -> 56 | I33: nc | J33: RG | K33: =IF(F33>2008,"Evaluation interne", " ") | L33: =IF(F33>2008, F33+20, " ") | M33: NC | BJ33: Chemins de roulement J3
A34: 1-FRANCE | B34: LHA | C34: Chemins de roulement J1 SUD 63T, soudures | E34: BOBINES | F34: 1970 | H34: =IF(F34="","",YEAR(TODAY())-F34) -> 56 | I34: nc | J34: RG | K34: =IF(F34>2008,"Evaluation interne", " ") | L34: =IF(F34>2008, F34+20, " ") | M34: NC | BJ34: Chemins de roulement J1, soudures
A35: 1-FRANCE | B35: LHA | C35: J1 Nord | D35: Pince | E35: STOCKAGE | H35: =IF(F35="","",YEAR(TODAY())-F35) | K35: =IF(F35>2008,"Evaluation interne", " ") | L35: =IF(F35>2008, F35+20, " ") | BJ35: J1 Nord
A36: 1-FRANCE | B36: LHA | C36: J2 Nord | D36: Elingue | E36: STOCKAGE | H36: =IF(F36="","",YEAR(TODAY())-F36) | K36: =IF(F36>2008,"Evaluation interne", " ") | L36: =IF(F36>2008, F36+20, " ") | BD36: EGT | BJ36: J2 Nord | BN36: 2025
A37: 1-FRANCE | B37: LHA | C37: J2 Sud | D37: Elingue | E37: PAL/PAVAR | H37: =IF(F37="","",YEAR(TODAY())-F37) | K37: =IF(F37>2008,"Evaluation interne", " ") | L37: =IF(F37>2008, F37+20, " ") | BD37: 2026 | BJ37: J2 Sud
A38: 1-FRANCE | B38: MCA | C38: Pont 63T XLHS SECAL | D38: Pince | E38: XL HS | F38: 2019 | H38: =IF(F38="","",YEAR(TODAY())-F38) -> 7 | K38: =IF(F38>2008,"Evaluation interne", " ") -> Evaluation interne | L38: =IF(F38>2008, F38+20, " ") -> 2039 | M38: N | N38: =F38+20 -> 2039 | O38: 40000 | AA38: 140000 | BJ38: Pont 63T XLHS SECAL | BM38: 2028
A39: 1-FRANCE | B39: MCA | C39: PINCE 50T XXL HS | E39: XXL HS | F39: 2019 | H39: =IF(F39="","",YEAR(TODAY())-F39) -> 7 | K39: =IF(F39>2008,"Evaluation interne", " ") -> Evaluation interne | L39: =IF(F39>2008, F39+20, " ") -> 2039 | N39: 2039
A40: 1-FRANCE | B40: MCA | C40: Pont 50/50 T XLHS SECAL | D40: Pince | E40: MAP XL | F40: 2019 | H40: =IF(F40="","",YEAR(TODAY())-F40) -> 7 | K40: =IF(F40>2008,"Evaluation interne", " ") -> Evaluation interne | L40: =IF(F40>2008, F40+20, " ") -> 2039 | M40: N | N40: =F40+39 -> 2058 | O40: 40000 | AD40: 170000 | BJ40: Pont 50/50 T XLHS SECAL | BM40: 2029
A41: 1-FRANCE | B41: MCA | C41: Pont 25 T PAL SEVAL | D41: Elingue | E41: PAL | F41: 2001 | H41: =IF(F41="","",YEAR(TODAY())-F41) -> 25 | J41: RGE 25 ans | K41: =IF(F41>2008,"Evaluation interne", " ") | L41: =IF(F41>2008, F41+20, " ") | M41: N | N41: =F41+39 -> 2040 | O41: 40000 | R41: 135000 | V41: 290000 | BD41: EGT | BJ41: Pont 25 T PAL SEVAL | BM41: 2025
...

Sheet SAUVPonts 160326 - maj
C2: A consolider | V2: A consolider
C3: EVS passée | V3: EVS passée
C4: En cas D'EVS négatif (changement pont) | V4: En cas D'EVS négatif (changement pont)
C5: Travaux spécifiques | V5: Travaux spécifiques
C6: RGE 25 ans | V6: RGE 25 ans
C7: RGE 50 ans | V7: RGE 50 ans
C8: EVS + tx suite EVS (réparation type soudures) | V8: EVS + tx suite EVS (réparation type soudures) OU dépenses obso (ex télécommandes)
B9: En Euros | K9: NEW ! | L9: NEW ! | M9: Evaluation Speciale | P9: OPEX usine = EVS + RGM après EVS + RGE après EVS (RGE "50 ans") CAPEX = RGE 25 ans + Installation nouveaux ponts (si EVS négatif) | BJ9: =COUNTA(BJ11:BJ182) -> 146 | BK9: ROADMAP SECURISATION DES PONTS
A10: PAYS | B10: Site | C10: Pont | D10: ACCESSOIRES : Pince ou Elingue | E10: Ligne de Presse ou utilisation | F10: MES | G10: Observations | H10: Age | I10: PRIX NEUF | J10: Travaux RG ou Installation Nouveau Pont | K10: Pont à évaluer en interne par Référent Levage (MES>2008) | L10: Année Evaluation Interne | M10: Evaluation Spéciale O/N | N10: EVS Année | O10: E/S Montant | P10: 2024 | Q10: 2025 OPEX DF (EVS et travaux préconisés) (EVS et travaux préconisés) | R10: 2025 RGE/RGM CAPEX IV | S10: 2025 ACHAT NEUF CAPEX IV | T10: 2026 OPEX DF (EVS et travaux préconisés) | U10: 2026 RGE/RGM CAPEX IV | V10: 2026 ACHAT NEUF CAPEX IV | W10: 2027 OPEX DF (EVS et travaux préconisés) | X10: 2027 RGE/RGM CAPEX IV | Y10: 2027 ACHAT NEUF CAPEX IV | Z10: 2028 OPEX DF (EVS et travaux préconisés) | AA10: 2028 RGE/RGM CAPEX IV | AB10: 2028 ACHAT NEUF CAPEX IV | AC10: 2029 OPEX DF (EVS et travaux préconisés) | AD10: 2029 RGE/RGM CAPEX IV | AE10: 2029 ACHAT NEUF CAPEX IV | AF10: 2030 OPEX DF (EVS et travaux préconisés) | AG10: 2030 RGE/RGM CAPEX IV | AH10: 2030 ACHAT NEUF CAPEX IV | AI10: 2031 OPEX DF (EVS et travaux préconisés) | AJ10: 2031 RGE/RGM CAPEX IV | AK10: 2031 ACHAT NEUF CAPEX IV | AL10: 2032 OPEX DF (EVS et travaux préconisés) | AM10: 2032 RGE/RGM CAPEX IV | AN10: 2032 ACHAT NEUF CAPEX IV | AO10: 2033 OPEX DF (EVS et travaux préconisés) | AP10: 2033 RGE/RGM CAPEX IV | AQ10: 2033 ACHAT NEUF CAPEX IV | AR10: 2034 OPEX DF (EVS et travaux préconisés) | AS10: 2034 RGE/RGM CAPEX IV | AT10: 2034 ACHAT NEUF CAPEX IV | AU10: 2035 OPEX DF (EVS et travaux préconisés) | AV10: 2035 RGE/RGM CAPEX IV | AW10: 2035 ACHAT NEUF CAPEX IV | AX10: 2036 OPEX DF (EVS et travaux préconisés) | AY10: 2036 RGE/RGM CAPEX IV | AZ10: 2036 ACHAT NEUF CAPEX IV | BA10: 2037 OPEX DF (EVS et travaux préconisés) | BB10: 2037 RGE/RGM CAPEX IV | BC10: 2037 ACHAT NEUF CAPEX IV | BD10: EGT | BE10: COMMENTAIRES ER SUIVI BAI | BK10: USAGE : Manutention et/ou Manipulation | BL10: TYPE : Automate ou Electromécanique | BM10: ROADMAP Capex Obsolescence | BN10: ROADMAP SECURISATION
A11: 1-FRANCE | B11: Chassis | C11: Pont E4 20T 48444 SEVAL/OMIS | F11: 2012 | G11: HORS SCOPE DEPT EMB | H11: =IF(F11="","",YEAR(TODAY())-F11) -> 14 | K11: =IF(F11>2008,"Evaluation interne", " ") -> Evaluation interne | L11: =IF(F11>2008, F11+20, " ") -> 2032 | M11: N | N11: =F11+39 -> 2051 | O11: 40000 | BJ11: Pont E4 20T 48444 SEVAL/OMIS
A12: 1-FRANCE | B12: Chassis | C12: Pont E0 46833 25 T KONECRANES | F12: 2010 | G12: HORS SCOPE DEPT EMB | H12: =IF(F12="","",YEAR(TODAY())-F12) -> 16 | J12: RGE | K12: =IF(F12>2008,"Evaluation interne", " ") -> Evaluation interne | L12: =IF(F12>2008, F12+20, " ") -> 2030 | M12: N | N12: =F12+39 -> 2049 | O12: 40000 | AU12: 40000 | BJ12: Pont E0 46833 25 T KONECRANES | BM12: 2035
A13: 1-FRANCE | B13: Chassis | C13: SP HH3 44839 25T ADC | F13: 2008 | G13: HORS SCOPE DEPT EMB | H13: =IF(F13="","",YEAR(TODAY())-F13) -> 18 | J13: RGE | K13: =IF(F13>2008,"Evaluation interne", " ") | L13: =IF(F13>2008, F13+20, " ") | M13: N | N13: =F13+39 -> 2047 | O13: 25000 | AO13: 50000 | BJ13: SP HH3 44839 25T ADC | BK13: Manipulation | BM13: 2033
A14: 1-FRANCE | B14: Chassis | C14: Pont E2 1470200822 4T SEVAL | F14: 2003 | G14: HORS SCOPE DEPT EMB | H14: =IF(F14="","",YEAR(TODAY())-F14) -> 23 | K14: =IF(F14>2008,"Evaluation interne", " ") | L14: =IF(F14>2008, F14+20, " ") | M14: N | N14: =F14+39 -> 2042 | O14: 40000 | BJ14: Pont E2 1470200822 4T SEVAL
A15: 1-FRANCE | B15: Chassis | C15: Pont E2' 1470200821 8/8 T DEMAG | F15: 2003 | G15: HORS SCOPE DEPT EMB | H15: =IF(F15="","",YEAR(TODAY())-F15) -> 23 | K15: =IF(F15>2008,"Evaluation interne", " ") | L15: =IF(F15>2008, F15+20, " ") | M15: N | N15: =F15+39 -> 2042 | O15: 40000 | BJ15: Pont E2' 1470200821 8/8 T DEMAG
A16: 1-FRANCE | B16: Chassis | C16: Pont E2 1470200820 14/14 T SEVAL | F16: 2003 | G16: HORS SCOPE DEPT EMB | H16: =IF(F16="","",YEAR(TODAY())-F16) -> 23 | J16: RGE | K16: =IF(F16>2008,"Evaluation interne", " ") | L16: =IF(F16>2008, F16+20, " ") | M16: N | N16: =F16+39 -> 2042 | O16: 40000 | AC16: 40000 | BJ16: Pont E2 1470200820 14/14 T SEVAL | BM16: 2029
A17: 1-FRANCE | B17: Chassis | C17: Pont (SP ?) E4 1470200756 8T | F17: 2003 | G17: HORS SCOPE DEPT EMB | H17: =IF(F17="","",YEAR(TODAY())-F17) -> 23 | J17: RGE | K17: =IF(F17>2008,"Evaluation interne", " ") | L17: =IF(F17>2008, F17+20, " ") | M17: N | N17: =F17+39 -> 2042 | O17: 40000 | Z17: 20000 | BJ17: Pont (SP ?) E4 1470200756 8T | BM17: 2028
A18: 1-FRANCE | B18: Chassis | C18: Pont E5 25 T 1470200554 SEVAL | F18: 2003 | G18: HORS SCOPE DEPT EMB | H18: =IF(F18="","",YEAR(TODAY())-F18) -> 23 | J18: RGE | K18: =IF(F18>2008,"Evaluation interne", " ") | L18: =IF(F18>2008, F18+20, " ") | M18: N | N18: =F18+39 -> 2042 | O18: 40000 | Z18: 50000 | BJ18: Pont E5 25 T 1470200554 SEVAL | BM18: 2028
A19: 1-FRANCE | B19: Chassis | C19: Pont E6 1470000240 50T SAMETO | F19: 2001 | G19: HORS SCOPE DEPT EMB | H19: =IF(F19="","",YEAR(TODAY())-F19) -> 25 | J19: RGE 25 ans | K19: =IF(F19>2008,"Evaluation interne", " ") | L19: =IF(F19>2008, F19+20, " ") | M19: N | N19: =F19+39 -> 2040 | O19: 40000 | X19: 170000 | BJ19: Pont E6 1470000240 50T SAMETO | BM19: 2027 | BN19: 2025
A20: 1-FRANCE | B20: Chassis | C20: Pont E6 1470001297 50/50T SAMETO | F20: 2001 | G20: HORS SCOPE DEPT EMB | H20: =IF(F20="","",YEAR(TODAY())-F20) -> 25 | J20: RGE 25 ans | K20: =IF(F20>2008,"Evaluation interne", " ") | L20: =IF(F20>2008, F20+20, " ") | M20: N | N20: =F20+39 -> 2040 | O20: 40000 | X20: 170000 | BJ20: Pont E6 1470001297 50/50T SAMETO | BM20: 2027
A21: 1-FRANCE | B21: Chassis | C21: Pont E0 1470000704 25 T SEVAL | F21: 2000 | G21: HORS SCOPE DEPT EMB | H21: =IF(F21="","",YEAR(TODAY())-F21) -> 26 | J21: RGE | K21: =IF(F21>2008,"Evaluation interne", " ") | L21: =IF(F21>2008, F21+20, " ") | M21: N | N21: =F21+39 -> 2039 | O21: 40000 | U21: 150000 | BJ21: Pont E0 1470000704 25 T SEVAL | BM21: 2026
A22: 1-FRANCE | B22: Chassis | C22: Pont E2 1479900509 16T SAMETO | F22: 1999 | G22: HORS SCOPE DEPT EMB | H22: =IF(F22="","",YEAR(TODAY())-F22) -> 27 | J22: RGE | K22: =IF(F22>2008,"Evaluation interne", " ") | L22: =IF(F22>2008, F22+20, " ") | M22: N | N22: =F22+39 -> 2038 | O22: 40000 | U22: 120000 | BJ22: Pont E2 1479900509 16T SAMETO | BM22: 2026
A23: 1-FRANCE | B23: Chassis | C23: Pont E1 759847 20T SAMETO | F23: 1994 | G23: HORS SCOPE DEPT EMB | H23: =IF(F23="","",YEAR(TODAY())-F23) -> 32 | J23: RGE | K23: =IF(F23>2008,"Evaluation interne", " ") | L23: =IF(F23>2008, F23+20, " ") | M23: N | N23: =F23+39 -> 2033 | O23: 40000 | U23: 150000 | BJ23: Pont E1 759847 20T SAMETO | BM23: 2026
A24: 1-FRANCE | B24: Chassis | C24: Pont E1 759848 20/20 T SAMETO (RGE 2019) | F24: 1994 | G24: HORS SCOPE DEPT EMB | H24: =IF(F24="","",YEAR(TODAY())-F24) -> 32 | K24: =IF(F24>2008,"Evaluation interne", " ") | L24: =IF(F24>2008, F24+20, " ") | M24: N | N24: =F24+39 -> 2033 | O24: 40000 | BJ24: Pont E1 759848 20/20 T SAMETO (RGE 2019)
A25: 1-FRANCE | B25: LHA | C25: Pont J12 63T | D25: Pince | E25: L08 | F25: 2006 | H25: =IF(F25="","",YEAR(TODAY())-F25) -> 20 | I25: ='DEMARCHE EVS'!B9 -> 950000 | J25: RGE | K25: =IF(F25>2008,"Evaluation interne", " ") | L25: =IF(F25>2008, F25+20, " ") | M25: NC | N25: =F25+39 -> 2045 | O25: 40000 | Z25: 60000 | BJ25: Pont J12 | BM25: 2028
A26: 1-FRANCE | B26: LHA | C26: Pont J11 63T | D26: Pince | E26: L11 | F26: 2006 | H26: =IF(F26="","",YEAR(TODAY())-F26) -> 20 | J26: RGE | K26: =IF(F26>2008,"Evaluation interne", " ") | L26: =IF(F26>2008, F26+20, " ") | N26: =F26+39 -> 2045 | O26: 40000 | AJ26: 170000 | BJ26: Pont J11 | BM26: 2029
A27: 1-FRANCE | B27: LHA | C27: Pince outils J11 | D27: PINCE | E27: L11 | F27: 1999 | H27: =IF(F27="","",YEAR(TODAY())-F27) -> 27 | J27: RG | K27: =IF(F27>2008,"Evaluation interne", " ") | L27: =IF(F27>2008, F27+20, " ") | M27: NC | R27: 100000
A28: 1-FRANCE | B28: LHA | C28: Pince à outil J12 | D28: PINCE | E28: STOCKAGE | F28: 1999 | H28: =IF(F28="","",YEAR(TODAY())-F28) -> 27 | I28: 220000 | J28: RGM | K28: =IF(F28>2008,"Evaluation interne", " ") | L28: =IF(F28>2008, F28+20, " ") | M28: NC | U28: 85000
A29: 1-FRANCE | B29: LHA | C29: Semi-portique N°1 J3 CHSL | E29: n fc | F29: 1979 | H29: =IF(F29="","",YEAR(TODAY())-F29) -> 47 | I29: 120000 | J29: RG | K29: =IF(F29>2008,"Evaluation interne", " ") | L29: =IF(F29>2008, F29+20, " ") | M29: N | N29: 2026 | O29: 20000 | T29: 20000 | BJ29: Semi-portique N°1 J3 CHSL | BK29: Manipulation
A30: 1-FRANCE | B30: LHA | C30: Semi-portique N°2 J3 CHSL (10T SAMETO?)-STOP 06/02 | E30: MAP/MAINTENANCE | F30: 1979 | H30: =IF(F30="","",YEAR(TODAY())-F30) -> 47 | I30: 120000 | J30: RG | K30: =IF(F30>2008,"Evaluation interne", " ") | L30: =IF(F30>2008, F30+20, " ") | M30: N | N30: 2026 | O30: 20000 | T30: =20000 -> 20000 | BJ30: Semi-portqiue N°2 J3 CHSL | BK30: Manipulation
A31: 1-FRANCE | B31: LHA | C31: Pont J1sud 63T | E31: 80%OUTILS / 20%BOBINES | F31: 1970 | H31: =IF(F31="","",YEAR(TODAY())-F31) -> 56 | J31: RGE 50 ans | K31: =IF(F31>2008,"Evaluation interne", " ") | L31: =IF(F31>2008, F31+20, " ") | M31: O | N31: 2035 | O31: 40000 | Q31: =40000 + 25000 -> 65000 | X31: 170000 | AU31: 40000 | AZ31: 1120000 | BJ31: Pont J1sud 63T | BM31: 2026
A32: 1-FRANCE | B32: LHA | C32: Pont J3 63/63T CAILLARD | E32: MAP/MAINTENANCE | F32: 1970 | H32: =IF(F32="","",YEAR(TODAY())-F32) -> 56 | I32: 1170000 | J32: 2026 prov pour travaux / Installation nouveaux ponts 2027 | K32: =IF(F32>2008,"Evaluation interne", " ") | L32: =IF(F32>2008, F32+20, " ") | M32: N | N32: 2026 | O32: 40000 | T32: 69000 | X32: 170000 | AB32: 1170000 | BJ32: Pont J3 63/63T CAILLARD | BM32: 2026
A33: 1-FRANCE | B33: LHA | C33: Chemins de roulement J3 | E33: MAP/MAINTENANCE | F33: 1970 | H33: =IF(F33="","",YEAR(TODAY())-F33) -> 56 | I33: nc | J33: RG | K33: =IF(F33>2008,"Evaluation interne", " ") | L33: =IF(F33>2008, F33+20, " ") | M33: NC | BJ33: Chemins de roulement J3
A34: 1-FRANCE | B34: LHA | C34: Chemins de roulement J1 SUD 63T, soudures | E34: BOBINES | F34: 1970 | H34: =IF(F34="","",YEAR(TODAY())-F34) -> 56 | I34: nc | J34: RG | K34: =IF(F34>2008,"Evaluation interne", " ") | L34: =IF(F34>2008, F34+20, " ") | M34: NC | BJ34: Chemins de roulement J1, soudures
A35: 1-FRANCE | B35: LHA | C35: J1 Nord | D35: Pince | E35: STOCKAGE | H35: =IF(F35="","",YEAR(TODAY())-F35) | K35: =IF(F35>2008,"Evaluation interne", " ") | L35: =IF(F35>2008, F35+20, " ") | BJ35: J1 Nord
A36: 1-FRANCE | B36: LHA | C36: J2 Nord | D36: Elingue | E36: STOCKAGE | H36: =IF(F36="","",YEAR(TODAY())-F36) | K36: =IF(F36>2008,"Evaluation interne", " ") | L36: =IF(F36>2008, F36+20, " ") | BD36: EGT | BJ36: J2 Nord | BN36: 2025
A37: 1-FRANCE | B37: LHA | C37: J2 Sud | D37: Elingue | E37: PAL/PAVAR | H37: =IF(F37="","",YEAR(TODAY())-F37) | K37: =IF(F37>2008,"Evaluation interne", " ") | L37: =IF(F37>2008, F37+20, " ") | BD37: 2026 | BJ37: J2 Sud
A38: 1-FRANCE | B38: MCA | C38: Pont 63T XLHS SECAL | D38: Pince | E38: XL HS | F38: 2019 | H38: =IF(F38="","",YEAR(TODAY())-F38) -> 7 | K38: =IF(F38>2008,"Evaluation interne", " ") -> Evaluation interne | L38: =IF(F38>2008, F38+20, " ") -> 2039 | M38: N | N38: =F38+20 -> 2039 | O38: 40000 | AA38: 140000 | BJ38: Pont 63T XLHS SECAL | BM38: 2028
A39: 1-FRANCE | B39: MCA | C39: PINCE 50T XXL HS | E39: XXL HS | F39: 2019 | H39: =IF(F39="","",YEAR(TODAY())-F39) -> 7 | K39: =IF(F39>2008,"Evaluation interne", " ") -> Evaluation interne | L39: =IF(F39>2008, F39+20, " ") -> 2039 | N39: 2039
A40: 1-FRANCE | B40: MCA | C40: Pont 50/50 T XLHS SECAL | D40: Pince | E40: MAP XL | F40: 2019 | H40: =IF(F40="","",YEAR(TODAY())-F40) -> 7 | K40: =IF(F40>2008,"Evaluation interne", " ") -> Evaluation interne | L40: =IF(F40>2008, F40+20, " ") -> 2039 | M40: N | N40: =F40+39 -> 2058 | O40: 40000 | AD40: 170000 | BJ40: Pont 50/50 T XLHS SECAL | BM40: 2029
A41: 1-FRANCE | B41: MCA | C41: Pont 25 T PAL SEVAL | D41: Elingue | E41: PAL | F41: 2001 | H41: =IF(F41="","",YEAR(TODAY())-F41) -> 25 | J41: RGE 25 ans | K41: =IF(F41>2008,"Evaluation interne", " ") | L41: =IF(F41>2008, F41+20, " ") | M41: N | N41: =F41+39 -> 2040 | O41: 40000 | R41: 135000 | V41: 290000 | BD41: EGT | BJ41: Pont 25 T PAL SEVAL | BM41: 2025
...

Sheet SYNTHESE ANNEE-5ans-10 ans
A1: =Ponts!R206 -> 0 | B1: =Ponts!S206 -> 0 | C1: =Ponts!T206 -> 0 | D1: =Ponts!U206 -> 0 | E1: =Ponts!V206 -> 0 | F1: =Ponts!W206 -> 2026 OPEX DF (EVS et travaux préconisés) | G1: =Ponts!X206 -> 2026 RGE/RGM CAPEX IV | H1: =Ponts!Y206 -> 2026 ACHAT NEUF CAPEX IV | ... AO1: =Ponts!BF206 -> 2037 ACHAT NEUF CAPEX IV
A2: =Ponts!R207 -> TOUS SITES | B2: =Ponts!S207 -> 0 | C2: =Ponts!T207 -> 372000 | D2: =Ponts!U207 -> 455000 | E2: =Ponts!V207 -> 0 | F2: =Ponts!W207 -> 656600 | G2: =Ponts!X207 -> 834000 | H2: =Ponts!Y207 -> 740000 | ... AO2: =Ponts!BF207 -> 0
A3: =Ponts!R208 -> CHASSIS | B3: =Ponts!S208 -> 0 | C3: =Ponts!T208 -> 0 | D3: =Ponts!U208 -> 0 | E3: =Ponts!V208 -> 0 | F3: =Ponts!W208 -> 0 | G3: =Ponts!X208 -> 420000 | H3: =Ponts!Y208 -> 0 | ... AO3: =Ponts!BF208 -> 0
A4: =Ponts!R209 -> HORS CHASSIS | B4: =Ponts!S209 -> 0 | C4: =Ponts!T209 -> 0 | D4: =Ponts!U209 -> 0 | E4: =Ponts!V209 -> 0 | F4: =Ponts!W209 -> 656600 | G4: =Ponts!X209 -> 414000 | H4: =Ponts!Y209 -> 740000 | ... AO4: =Ponts!BF209 -> 0
B9: 2027 | C9: 2028 | D9: 2029 | E9: 2030 | F9: 2031 | J9: 2026 | K9: an | L9: 5 ANS | M9: 5 ANS | N9: 10 ANS | O9: 10 ANS
A10: CAP EVS | B10: =$K$10 -> 328000 | C10: =$K$10 -> 328000 | D10: =$K$10 -> 328000 | E10: =$K$10 -> 328000 | F10: =$K$10 -> 328000 | H10: 40000 | I10: EVS à réaliser | J10: =N10/10 -> 8.2 | K10: =$H$10*J10 -> 328000 | L10: 39 | M10: =$H$11*L10 -> 6630000 | N10: 82 | O10: =$H$11*N10 -> 13940000
A11: CAP RGE | B11: =$K$11 -> 1224000 | C11: =$K$11 -> 1224000 | D11: =$K$11 -> 1224000 | E11: =$K$11 -> 1224000 | F11: =$K$11 -> 1224000 | H11: 170000 | I11: RGE 25 ans | J11: =N11/10 -> 7.2 | K11: =$H$11*J11 -> 1224000 | L11: 31 | M11: =L11*H11 -> 5270000 | N11: 72 | O11: =N11*H11 -> 12240000
A12: CAP event gates | B12: =$K$12 -> 1205454.5 | C12: =$K$12 -> 1205454.5 | D12: =$K$12 -> 1205454.5 | E12: =$K$12 -> 1205454.5 | F12: =$K$12 -> 1205454.5 | H12: 80000 | I12: EVENT GATES | J12: =N12/11 -> 7.0909091 | K12: =$H$11*J12 -> 1205454.5 | L12: =5*9 -> 45 | M12: =L12*H12 -> 3600000 | N12: 78 | O12: =N12*H12 -> 6240000
A13: Dépenses OPEX usine (EVS) | B13: =Ponts!Z209 -> 357000 | C13: =Ponts!AC209 -> 188600 | D13: =Ponts!AF209 -> 65000 | E13: =Ponts!AI209 -> 153000 | F13: =Ponts!AL209 -> 5000
A14: OBJECTIF - 0 PONT NEUF | B14: =Ponts!AA209 -> 2810000 | C14: =Ponts!AD209 -> 1160000 | D14: =Ponts!AG209 -> 1190000 | E14: =Ponts!AJ209 -> 1870000 | F14: =Ponts!AM209 -> 1320000 | M14: =SUM(K10:K12) -> 2757454.5 | N14: =SUM(M10:M12) -> 15500000 | O14: =SUM(O10:O12) -> 32420000
A15: CAPEX IV JANVIER | B15: 6740000 | C15: 4070000 | D15: 3470000 | E15: 1950000 | F15: 1950000
A16: CAPEX IV FEV | B16: ='SAUVPonts FEV26'!X210+'SAUVPonts FEV26'!Y210 -> 4595000 | C16: ='SAUVPonts FEV26'!AA210+'SAUVPonts FEV26'!AB210 -> 5060000 | D16: ='SAUVPonts FEV26'!AD210+'SAUVPonts FEV26'!AE210 -> 1190000 | E16: ='SAUVPonts FEV26'!AG210+'SAUVPonts FEV26'!AH210 -> 2570000 | F16: ='SAUVPonts FEV26'!AJ210+'SAUVPonts FEV26'!AK210 -> 2170000
A17: CAPEX IV MARS | B17: =Ponts!AA209+Ponts!AB209 -> 5045000 | C17: =Ponts!AD209+Ponts!AE209 -> 4090000 | D17: =Ponts!AG209+Ponts!AH209 -> 1190000 | E17: =Ponts!AJ209+Ponts!AK209 -> 1870000 | F17: =Ponts!AM209+Ponts!AN209 -> 2170000 | J17: 2026 | K17: 2027 | L17: 2028 | M17: 2029 | N17: 2030 | O17: 2031
A18: CAPEX IV AVRIL | I18: EVS | J18: 656000 | K18: =B13 -> 357000 | L18: =C13 -> 188600 | M18: =D13 -> 65000 | N18: =E13 -> 153000 | O18: =F13 -> 5000
A19: CAPEX IV MAI | I19: GAINS | J19: 740000 | K19: =B16-B14 -> 1785000 | L19: =C16-C14 -> 3900000 | M19: =D16-D14 -> 0 | N19: =E16-E14 -> 700000 | O19: =F16-F14 -> 850000
A20: CAPEX IV JUIN
A21: CAPEX IV JUILLET
A22: CAPEX IV SEPTEMBRE
A23: CAPEX IV OCTOBRE
A24: CAPEX IV NOVEMBRE
A25: CAPEX IV DECEMBRE
B50: BUDGET | C50: POLITIQUE METIER | D50: 2026 | E50: 2027-2031 | F50: 2032-2036
B51: OPEX DF | C51: EVS | D51: =Ponts!W209/1000 -> 656.6 | E51: =Ponts!AB225/1000 -> 768.6 | F51: =Ponts!AQ225/1000 -> 457.5
B52: CAPEX 65307 | C52: RGE RGM | D52: =Ponts!X209/1000 -> 414 | E52: =Ponts!AB226/1000 -> 8350 | F52: =Ponts!AQ226/1000 -> 2340
B53: CAPEX 65307 | C53: ACHAT PONTS NEUFS | D53: =Ponts!Y209/1000 -> 740 | E53: =Ponts!AB227/1000 -> 6015 | F53: =Ponts!AQ227/1000 -> 1120
B54: CAPEX IV | C54: IA | D54: ='EVENT GATES'!E22/1000 -> 499 | E54: ='EVENT GATES'!F22/1000*5 -> 3095 | F54: =E54 -> 3095

Sheet DEMARCHE EVS
A1: à partir de 2006 | B1: 20 ans pour faire EVS sauf exception et à déterminer au cas par cas
A2: avant 2006 | B2: 40 ans
A3: EVS | B3: selon pb : achat pont neuf | E3: RGEM
A4: PONT 5T | B4: 70000
A5: PONT -25T | B5: 500000 | C5: STD RENAULT
A6: PONT 32T | B6: 675000 | C6: STD RENAULT | D6: si standard fournisseur : -50% (FEM < M6) | E6: +20K si dble crochet | F6: 650K/700K
A7: PONT 40T | B7: 725000 | C7: STD RENAULT | D7: si standard fournisseur : -50% (FEM < M6) | E7: +20K si dble crochet | F7: 700K/750K
A8: PONT 50T | B8: 840000 | C8: STD RENAULT | D8: si standard fournisseur : -50% (FEM < M6) | E8: +30K si dble crochet | F8: 800K/880K
A9: PONT 63T | B9: 950000 | C9: STD RENAULT | D9: si standard fournisseur : -50% (FEM < M6) | E9: +30K si dble crochet | F9: 900K/1000K
A10: PONT 63T/32
A11: RGEM 1 CROCHET
A12: RGEM DEUX CROCHETS
A15: année MES | B15: EVS +39 | C15: condition
A16: année MES | B16: EVS +20 (si après 2006) | C16: nb de cycles éffectués / groupe FEM
B17: évaluation interne = enquête Daniel, avec calcul de la durée de vie suputée
B18: ajouter colonne "pont à évaluer en interne" (>MES 2008)par référent levage sur durée de vie passée et restante
